// RxJS v6+
import { throwError, of } from 'rxjs';
import { catchError } from 'rxjs/operators';
//emit error
const source = throwError('This is an error!');
//gracefully handle error, returning observable with error message
const example = source.pipe(catchError(val => of(`I caught: ${val}`)));
//output: 'I caught: This is an error'
const subscribe = example.subscribe(val => console.log(val));